<?xml version="1.0"?>
<robot>

  <macro name="mini_gripper" params="name parent">
    <!-- Static Side -->
    <joint name="${name}_static_joint" type="fixed">
      <axis xyz="0 0 1" />
      <origin xyz="0.1 0 0" rpy="0 0 0" />
      <parent link="${parent}_link"/>
      <child link="${name}_link"/>
    </joint>
    <link name="${name}_link">
      <visual name="${name}_static_visual">
        <origin xyz="-0.05 0.025 0" rpy="-1.57 0 0"/>
        <geometry name="${name}_static_visual_geom">
          <mesh filename="package://mini_max_defs/meshes/gripper.stl" />
        </geometry>
        <material name="Grey" />
      </visual>
      <!-- TODO: add collision -->
    </link>
    <!-- Actuated Side -->
    <joint name="${name}_joint" type="revolute">
      <axis xyz="0 0 1" />
      <origin xyz="0.05 -0.025 0" rpy="0 0 0" />
      <limit lower="-1.57"  upper="1.57" effort="5.0" velocity="5" />
      <parent link="${parent}_link"/>
      <child link="finger_link"/>
    </joint>
    <link name="finger_link">
      <visual name="finger_visual">
        <origin xyz="0 0 0" rpy="1.57 0 0" />
        <geometry name="finger_visual_geom">
          <mesh filename="package://mini_max_defs/meshes/gripper.stl" />
        </geometry>
        <material name="Grey" />
      </visual>
      <!-- TODO: add collision -->
    </link>
  </macro>

</robot>
