<?xml version="1.0"?>
<robot>

  <macro name="mini_gripper" params="name parent">
    <joint name="${name}_joint" type="fixed">
      <axis xyz="0 0 1" />
      <origin xyz="${0.08255+0.0254} 0 0" rpy="0 0 0" />
      <parent link="${parent}_link"/>
      <child link="${name}_link"/>
    </joint>
    <link name="${name}_link">
      <visual>
        <origin xyz="-0.0254 0.0381 -0.01" rpy="1.57 3.14 0" />
        <geometry>
          <mesh filename="package://mini_max_defs/meshes/gripper-body.stl" />
        </geometry>
        <material name="Black" />
      </visual>
      <!-- TODO: add collision -->
    </link>

    <joint name="${name}_left_joint" type="prismatic">
      <axis xyz="0 1 0" />
      <limit lower="0.0" upper="0.0254" effort="1" velocity="1"/>
      <origin xyz="0 0 0" rpy="0 0 0" />
      <parent link="${name}_link"/>
      <child link="${name}_left_link"/>
    </joint>
    <link name="${name}_left_link">
      <visual>
        <origin xyz="-0.0254 0 0" rpy="1.57 3.14 0"/>
        <geometry>
          <mesh filename="package://mini_max_defs/meshes/gripper-finger.stl" />
        </geometry>
        <material name="Orange" />
      </visual>
    </link>

    <joint name="${name}_right_joint" type="prismatic">
      <axis xyz="0 1 0" />
      <limit lower="0.0" upper="0.0254" effort="1" velocity="1"/>
      <origin xyz="0 0 0" rpy="0 0 0" />
      <parent link="${name}_link"/>
      <child link="${name}_right_link"/>
    </joint>
    <link name="${name}_right_link">
      <visual>
        <origin xyz="-0.0254 0 0" rpy="-1.57 3.14 0"/>
        <geometry>
          <mesh filename="package://mini_max_defs/meshes/gripper-finger.stl" />
        </geometry>
        <material name="Orange" />
      </visual>
    </link>
  </macro>

</robot>
